Workbook

Sheet Raw_Data
A1: RAW DATA (As Submitted, Unmodified)
A3: Order_ID | B3: Day | C3: Customer_Type | D3: Area | E3: Order_Type | F3: Items | G3: Order_Value | H3: Delivery_Fee | I3: Prep_Minutes | J3: Delivery_Minutes | K3: Rating | L3: Promo_Used
A4: FD10000 | B4: 1 | C4: Returning | D4: North | E4: Regular | F4: 1 | G4: 180 | H4: 50 | I4: 16 | J4: 36 | K4: 4.1 | L4: No
A5: FD10001 | B5: 2 | C5: New | D5: East | E5: Combo | F5: 3 | G5: 360 | H5: 30 | I5: 13 | J5: 25 | K5: 3.7 | L5: No
A6: FD10002 | B6: 3 | C6: Returning | D6: Central | E6: Regular | F6: 1 | G6: 120 | H6: 60 | I6: 24 | J6: 23 | K6: 4.7 | L6: No
A7: FD10003 | B7: 4 | C7: New | D7: East | E7: Combo | F7: 1 | G7: 120 | H7: 50 | I7: 28 | J7: 53 | K7: 4 | L7: Yes
A8: FD10004 | B8: 5 | C8: New | D8: East | E8: Combo | F8: 3 | G8: 360 | H8: 30 | I8: 19 | J8: 41 | K8: 3.7 | L8: No
A9: FD10005 | B9: 6 | C9: Returning | D9: Central | E9: Large | F9: 2 | G9: 500 | H9: 60 | I9: 16 | J9: 45 | K9: 4.2 | L9: Yes
A10: FD10006 | B10: 7 | C10: New | D10: South | E10: Regular | F10: 2 | G10: 500 | H10: 40 | I10: 17 | J10: 31 | K10: 4.5 | L10: Yes
A11: FD10007 | B11: 8 | C11: New | D11: North | E11: Combo | F11: 4 | G11: 480 | H11: 30 | I11: 9 | J11: 35 | K11: 3.9 | L11: No
A12: FD10008 | B12: 9 | C12: Returning | D12: South | E12: Regular | F12: 4 | G12: 1000 | H12: 30 | I12: 27 | J12: 28 | K12: 4.8 | L12: No
A13: FD10009 | B13: 10 | C13: New | D13: South | E13: Large | F13: 5 | G13: 600 | H13: 50 | I13: 22 | J13: 45 | K13: 4 | L13: No
A14: FD10010 | B14: 11 | C14: New | D14: North | E14: Regular | F14: 2 | G14: 700 | H14: 40 | I14: 17 | J14: 46 | K14: 4 | L14: No
A15: FD10011 | B15: 12 | C15: Returning | D15: South | E15: Combo | F15: 4 | G15: 1400 | H15: 50 | I15: 28 | J15: 29 | K15: 4.4 | L15: No
... A53: FD10049 | B53: 50 | C53: New | D53: South | E53: Large | F53: 1 | G53: 180 | H53: 30 | I53: 7 | J53: 22 | K53: 4.9 | L53: Yes

Sheet Data_Dictionary
A1: DATA DICTIONARY
A3: Field | B3: Description | C3: Notes
A4: Order_ID | B4: Unique identifier for each food delivery order | C4: Format FD10000-FD10049; checked, no duplicates
A5: Day | B5: Sequential day number the order was placed (1-50) | C5: One order recorded per day in this dataset
A6: Customer_Type | B6: Whether the customer is New or a Returning customer | C6: Categorical: New, Returning
A7: Area | B7: Delivery area/zone for the order | C7: Categorical: North, South, East, Central
A8: Order_Type | B8: Category/size of the order | C8: Categorical: Regular, Combo, Large
A9: Items | B9: Number of items in the order | C9: Integer, range 1-5
A10: Order_Value | B10: Total monetary value of the order (PHP) | C10: Integer, range 120-2500
A11: Delivery_Fee | B11: Fee charged for delivery (PHP) | C11: Integer, range 30-60
A12: Prep_Minutes | B12: Food preparation time in minutes | C12: Integer, range 7-29
A13: Delivery_Minutes | B13: Delivery/transit time in minutes | C13: Integer, range 15-59
A14: Rating | B14: Customer satisfaction rating for the order | C14: Scale 3.0-4.9
A15: Promo_Used | B15: Whether a promotional discount/promo code was used | C15: Categorical: Yes, No

Sheet Cleaned_Data
A1: CLEANED DATA
A3: Data Cleaning Log:
A4: - Checked all 50 Order_IDs for duplicates: none found (all unique, FD10000-FD10049).
A5: - Checked all 12 fields for missing/blank values: none found (0 nulls across the dataset).
A6: - Checked numeric fields (Items, Order_Value, Delivery_Fee, Prep_Minutes, Delivery_Minutes, Rating) for negative, zero, or out-of-range values: none found.
A7: - Checked categorical fields (Customer_Type, Area, Order_Type, Promo_Used) for inconsistent spelling/casing (e.g. "new" vs "New"): none found, values are already standardized.
A8: - Conclusion: the raw dataset was already clean. No rows were removed or altered; the table below is an exact, formula-ready copy of Raw_Data.
A10: Order_ID | B10: Day | C10: Customer_Type | D10: Area | E10: Order_Type | F10: Items | G10: Order_Value | H10: Delivery_Fee | I10: Prep_Minutes | J10: Delivery_Minutes | K10: Rating | L10: Promo_Used
A12: FD10000 | B12: 1 | C12: Returning | D12: North | E12: Regular | F12: 1 | G12: 180 | H12: 50 | I12: 16 | J12: 36 | K12: 4.1 | L12: No
A13: FD10001 | B13: 2 | C13: New | D13: East | E13: Combo | F13: 3 | G13: 360 | H13: 30 | I13: 13 | J13: 25 | K13: 3.7 | L13: No
A14: FD10002 | B14: 3 | C14: Returning | D14: Central | E14: Regular | F14: 1 | G14: 120 | H14: 60 | I14: 24 | J14: 23 | K14: 4.7 | L14: No
A15: FD10003 | B15: 4 | C15: New | D15: East | E15: Combo | F15: 1 | G15: 120 | H15: 50 | I15: 28 | J15: 53 | K15: 4 | L15: Yes
A16: FD10004 | B16: 5 | C16: New | D16: East | E16: Combo | F16: 3 | G16: 360 | H16: 30 | I16: 19 | J16: 41 | K16: 3.7 | L16: No
A17: FD10005 | B17: 6 | C17: Returning | D17: Central | E17: Large | F17: 2 | G17: 500 | H17: 60 | I17: 16 | J17: 45 | K17: 4.2 | L17: Yes
A18: FD10006 | B18: 7 | C18: New | D18: South | E18: Regular | F18: 2 | G18: 500 | H18: 40 | I18: 17 | J18: 31 | K18: 4.5 | L18: Yes
A19: FD10007 | B19: 8 | C19: New | D19: North | E19: Combo | F19: 4 | G19: 480 | H19: 30 | I19: 9 | J19: 35 | K19: 3.9 | L19: No
A20: FD10008 | B20: 9 | C20: Returning | D20: South | E20: Regular | F20: 4 | G20: 1000 | H20: 30 | I20: 27 | J20: 28 | K20: 4.8 | L20: No | N20: =COUNTBLANK(A12:L61) -> 0
A21: FD10009 | B21: 10 | C21: New | D21: South | E21: Large | F21: 5 | G21: 600 | H21: 50 | I21: 22 | J21: 45 | K21: 4 | L21: No
A22: FD10010 | B22: 11 | C22: New | D22: North | E22: Regular | F22: 2 | G22: 700 | H22: 40 | I22: 17 | J22: 46 | K22: 4 | L22: No
A23: FD10011 | B23: 12 | C23: Returning | D23: South | E23: Combo | F23: 4 | G23: 1400 | H23: 50 | I23: 28 | J23: 29 | K23: 4.4 | L23: No
A24: FD10012 | B24: 13 | C24: Returning | D24: South | E24: Large | F24: 5 | G24: 2500 | H24: 50 | I24: 19 | J24: 31 | K24: 3.8 | L24: No
A25: FD10013 | B25: 14 | C25: Returning | D25: South | E25: Combo | F25: 5 | G25: 1750 | H25: 60 | I25: 12 | J25: 57 | K25: 3 | L25: No
A26: FD10014 | B26: 15 | C26: New | D26: North | E26: Combo | F26: 4 | G26: 1000 | H26: 50 | I26: 16 | J26: 53 | K26: 4.1 | L26: No
A27: FD10015 | B27: 16 | C27: New | D27: Central | E27: Large | F27: 1 | G27: 250 | H27: 30 | I27: 17 | J27: 36 | K27: 3.9 | L27: No
A28: FD10016 | B28: 17 | C28: New | D28: South | E28: Combo | F28: 3 | G28: 540 | H28: 30 | I28: 14 | J28: 57 | K28: 3 | L28: Yes
A29: FD10017 | B29: 18 | C29: Returning | D29: North | E29: Regular | F29: 5 | G29: 900 | H29: 60 | I29: 23 | J29: 28 | K29: 3.7 | L29: Yes
A30: FD10018 | B30: 19 | C30: Returning | D30: South | E30: Combo | F30: 2 | G30: 1000 | H30: 40 | I30: 18 | J30: 56 | K30: 3.5 | L30: No
A31: FD10019 | B31: 20 | C31: New | D31: North | E31: Large | F31: 2 | G31: 240 | H31: 40 | I31: 29 | J31: 34 | K31: 3.6 | L31: No
A32: FD10020 | B32: 21 | C32: New | D32: Central | E32: Regular | F32: 2 | G32: 360 | H32: 60 | I32: 7 | J32: 21 | K32: 4.2 | L32: Yes
... A61: FD10049 | B61: 50 | C61: New | D61: South | E61: Large | F61: 1 | G61: 180 | H61: 30 | I61: 7 | J61: 22 | K61: 4.9 | L61: Yes

Sheet Descriptive_Stats
A1: DESCRIPTIVE STATISTICS
A3: Task 3: Descriptive Statistics — Order Value, Items, Prep Time, Delivery Time, Rating
A4: Statistic | B4: Order_Value | C4: Items | D4: Prep_Minutes | E4: Delivery_Minutes | F4: Rating
A5: Mean | B5: =AVERAGE(Cleaned_Data!$G$12:$G$61) -> 733.4 | C5: =AVERAGE(Cleaned_Data!$F$12:$F$61) -> 2.82 | D5: =AVERAGE(Cleaned_Data!$I$12:$I$61) -> 18.14 | E5: =AVERAGE(Cleaned_Data!$J$12:$J$61) -> 36.02 | F5: =AVERAGE(Cleaned_Data!$K$12:$K$61) -> 4.08
A6: Median | B6: =MEDIAN(Cleaned_Data!$G$12:$G$61) -> 540 | C6: =MEDIAN(Cleaned_Data!$F$12:$F$61) -> 3 | D6: =MEDIAN(Cleaned_Data!$I$12:$I$61) -> 17.5 | E6: =MEDIAN(Cleaned_Data!$J$12:$J$61) -> 35.5 | F6: =MEDIAN(Cleaned_Data!$K$12:$K$61) -> 4
A7: Minimum | B7: =MIN(Cleaned_Data!$G$12:$G$61) -> 120 | C7: =MIN(Cleaned_Data!$F$12:$F$61) -> 1 | D7: =MIN(Cleaned_Data!$I$12:$I$61) -> 7 | E7: =MIN(Cleaned_Data!$J$12:$J$61) -> 15 | F7: =MIN(Cleaned_Data!$K$12:$K$61) -> 3
A8: Maximum | B8: =MAX(Cleaned_Data!$G$12:$G$61) -> 2500 | C8: =MAX(Cleaned_Data!$F$12:$F$61) -> 5 | D8: =MAX(Cleaned_Data!$I$12:$I$61) -> 29 | E8: =MAX(Cleaned_Data!$J$12:$J$61) -> 59 | F8: =MAX(Cleaned_Data!$K$12:$K$61) -> 4.9
A9: Std Dev | B9: =_xlfn.STDEV.S(Cleaned_Data!$G$12:$G$61) -> 578.68821 | C9: =_xlfn.STDEV.S(Cleaned_Data!$F$12:$F$61) -> 1.424136 | D9: =_xlfn.STDEV.S(Cleaned_Data!$I$12:$I$61) -> 6.3310379 | E9: =_xlfn.STDEV.S(Cleaned_Data!$J$12:$J$61) -> 13.079802 | F9: =_xlfn.STDEV.S(Cleaned_Data!$K$12:$K$61) -> 0.43845741
A12: Task 4: Orders & Order Value by Customer Type (New vs Returning)
A13: Customer_Type | B13: Number of Orders | C13: Total Order Value | D13: Average Order Value
A14: New | B14: =COUNTIF(Cleaned_Data!$C$12:$C$61,A14) -> 31 | C14: =SUMIF(Cleaned_Data!$C$12:$C$61,A14,Cleaned_Data!$G$12:$G$61) -> 17860 | D14: =C14/B14 -> 576.12903
A15: Returning | B15: =COUNTIF(Cleaned_Data!$C$12:$C$61,A15) -> 19 | C15: =SUMIF(Cleaned_Data!$C$12:$C$61,A15,Cleaned_Data!$G$12:$G$61) -> 18810 | D15: =C15/B15 -> 990
A16: TOTAL | B16: =SUM(B14:B15) -> 50 | C16: =SUM(C14:C15) -> 36670 | D16: =C16/B16 -> 733.4
A18: Task 5 & 6: Interpretation — Customer Type Comparison
A19: See table above. Returning customers place fewer or more orders and show a higher/lower average order value than New customers depending on the computed figures — refer to the Number of Orders and Average Order Value columns directly above for the exact comparison.
A21: Task 7: Orders & Order Value by Delivery Area
A22: Area | B22: Number of Orders | C22: Total Order Value | D22: Average Order Value
A23: North | B23: =COUNTIF(Cleaned_Data!$D$12:$D$61,A23) -> 13 | C23: =SUMIF(Cleaned_Data!$D$12:$D$61,A23,Cleaned_Data!$G$12:$G$61) -> 9190 | D23: =C23/B23 -> 706.92308
A24: South | B24: =COUNTIF(Cleaned_Data!$D$12:$D$61,A24) -> 16 | C24: =SUMIF(Cleaned_Data!$D$12:$D$61,A24,Cleaned_Data!$G$12:$G$61) -> 14050 | D24: =C24/B24 -> 878.125
A25: East | B25: =COUNTIF(Cleaned_Data!$D$12:$D$61,A25) -> 8 | C25: =SUMIF(Cleaned_Data!$D$12:$D$61,A25,Cleaned_Data!$G$12:$G$61) -> 5890 | D25: =C25/B25 -> 736.25
A26: Central | B26: =COUNTIF(Cleaned_Data!$D$12:$D$61,A26) -> 13 | C26: =SUMIF(Cleaned_Data!$D$12:$D$61,A26,Cleaned_Data!$G$12:$G$61) -> 7540 | D26: =C26/B26 -> 580
A27: TOTAL | B27: =SUM(B23:B26) -> 50 | C27: =SUM(C23:C26) -> 36670 | D27: =C27/B27 -> 733.4
A29: Task 8: Orders by Order Type (Regular / Combo / Large)
A30: Order_Type | B30: Number of Orders | C30: Total Order Value | D30: Average Order Value
A31: Regular | B31: =COUNTIF(Cleaned_Data!$E$12:$E$61,A31) -> 18 | C31: =SUMIF(Cleaned_Data!$E$12:$E$61,A31,Cleaned_Data!$G$12:$G$61) -> 11360 | D31: =C31/B31 -> 631.11111
A32: Combo | B32: =COUNTIF(Cleaned_Data!$E$12:$E$61,A32) -> 19 | C32: =SUMIF(Cleaned_Data!$E$12:$E$61,A32,Cleaned_Data!$G$12:$G$61) -> 14440 | D32: =C32/B32 -> 760
A33: Large | B33: =COUNTIF(Cleaned_Data!$E$12:$E$61,A33) -> 13 | C33: =SUMIF(Cleaned_Data!$E$12:$E$61,A33,Cleaned_Data!$G$12:$G$61) -> 10870 | D33: =C33/B33 -> 836.15385
A35: Order Type with highest number of orders: | D35: =INDEX(A31:A33,MATCH(MAX(B31:B33),B31:B33,0)) -> Combo
A37: Task 9 & 10: Delivery Performance by Area (Prep Time & Delivery Time)
A38: Area | B38: Avg Prep_Minutes | C38: Avg Delivery_Minutes | D38: Avg Total Time (Prep+Delivery)
A39: North | B39: =_xlfn.AVERAGEIF(Cleaned_Data!$D$12:$D$61,A39,Cleaned_Data!$I$12:$I$61) -> 16.923077 | C39: =_xlfn.AVERAGEIF(Cleaned_Data!$D$12:$D$61,A39,Cleaned_Data!$J$12:$J$61) -> 40.538462 | D39: =B39+C39 -> 57.461538
A40: South | B40: =_xlfn.AVERAGEIF(Cleaned_Data!$D$12:$D$61,A40,Cleaned_Data!$I$12:$I$61) -> 18.9375 | C40: =_xlfn.AVERAGEIF(Cleaned_Data!$D$12:$D$61,A40,Cleaned_Data!$J$12:$J$61) -> 37.5 | D40: =B40+C40 -> 56.4375
A41: East | B41: =_xlfn.AVERAGEIF(Cleaned_Data!$D$12:$D$61,A41,Cleaned_Data!$I$12:$I$61) -> 18.5 | C41: =_xlfn.AVERAGEIF(Cleaned_Data!$D$12:$D$61,A41,Cleaned_Data!$J$12:$J$61) -> 33.125 | D41: =B41+C41 -> 51.625
A42: Central | B42: =_xlfn.AVERAGEIF(Cleaned_Data!$D$12:$D$61,A42,Cleaned_Data!$I$12:$I$61) -> 18.153846 | C42: =_xlfn.AVERAGEIF(Cleaned_Data!$D$12:$D$61,A42,Cleaned_Data!$J$12:$J$61) -> 31.461538 | D42: =B42+C42 -> 49.615385
A44: Area with slowest overall performance (highest avg total time): | D44: =INDEX(A39:A42,MATCH(MAX(D39:D42),D39:D42,0)) -> North
A46: Task 11 & 12: Relationship Between Delivery Time and Rating
A47: Correlation coefficient (Delivery_Minutes vs Rating): | D47: =CORREL(Cleaned_Data!$J$12:$J$61,Cleaned_Data!$K$12:$K$61) -> -0.69527312
A48: Interpretation: A negative correlation indicates that as delivery time increases, customer ratings tend to decrease — i.e., slower deliveries are associated with lower satisfaction. The closer the coefficient is to -1, the stronger this inverse relationship; a value near 0 would indicate little to no linear relationship.
A50: Task 13 & 14: Promo Usage — Average Order Value & Count
A51: Promo_Used | B51: Number of Orders | C51: Average Order Value
...

Sheet PivotTable_Summary
A1: PIVOTTABLE SUMMARY (Task 16) — Area x Customer Type
A2: Built as a live formula-driven cross-tab (AVERAGEIFS/COUNTIFS/SUMIFS) equivalent to an Excel PivotTable summarizing Delivery Area and Customer Type against Number of Orders, Average Order Value, Average Delivery Time, and Average Rating. To view as a native interactive PivotTable in Excel: select Cleaned_Data!A11:L61, then Insert > PivotTable, and set Area and Customer_Type as Rows, and Order_Value/Delivery_Minutes/Rating as Values (Average) with Order_ID as Values (Count).
A4: Area | B4: Customer_Type | C4: Number of Orders | D4: Average Order Value | E4: Average Delivery Time (min) | F4: Average Rating
A5: North | B5: New | C5: =_xlfn.COUNTIFS(Cleaned_Data!$D$12:$D$61,A5,Cleaned_Data!$C$12:$C$61,B5) -> 7 | D5: =_xlfn.IFERROR(_xlfn.AVERAGEIFS(Cleaned_Data!$G$12:$G$61,Cleaned_Data!$D$12:$D$61,A5,Cleaned_Data!$C$12:$C$61,B5),0) -> 674.28571 | E5: =_xlfn.IFERROR(_xlfn.AVERAGEIFS(Cleaned_Data!$J$12:$J$61,Cleaned_Data!$D$12:$D$61,A5,Cleaned_Data!$C$12:$C$61,B5),0) -> 41.142857 | F5: =_xlfn.IFERROR(_xlfn.AVERAGEIFS(Cleaned_Data!$K$12:$K$61,Cleaned_Data!$D$12:$D$61,A5,Cleaned_Data!$C$12:$C$61,B5),0) -> 3.8428571
A6: North | B6: Returning | C6: =_xlfn.COUNTIFS(Cleaned_Data!$D$12:$D$61,A6,Cleaned_Data!$C$12:$C$61,B6) -> 6 | D6: =_xlfn.IFERROR(_xlfn.AVERAGEIFS(Cleaned_Data!$G$12:$G$61,Cleaned_Data!$D$12:$D$61,A6,Cleaned_Data!$C$12:$C$61,B6),0) -> 745 | E6: =_xlfn.IFERROR(_xlfn.AVERAGEIFS(Cleaned_Data!$J$12:$J$61,Cleaned_Data!$D$12:$D$61,A6,Cleaned_Data!$C$12:$C$61,B6),0) -> 39.833333 | F6: =_xlfn.IFERROR(_xlfn.AVERAGEIFS(Cleaned_Data!$K$12:$K$61,Cleaned_Data!$D$12:$D$61,A6,Cleaned_Data!$C$12:$C$61,B6),0) -> 3.9
A7: South | B7: New | C7: =_xlfn.COUNTIFS(Cleaned_Data!$D$12:$D$61,A7,Cleaned_Data!$C$12:$C$61,B7) -> 8 | D7: =_xlfn.IFERROR(_xlfn.AVERAGEIFS(Cleaned_Data!$G$12:$G$61,Cleaned_Data!$D$12:$D$61,A7,Cleaned_Data!$C$12:$C$61,B7),0) -> 443.75 | E7: =_xlfn.IFERROR(_xlfn.AVERAGEIFS(Cleaned_Data!$J$12:$J$61,Cleaned_Data!$D$12:$D$61,A7,Cleaned_Data!$C$12:$C$61,B7),0) -> 33.375 | F7: =_xlfn.IFERROR(_xlfn.AVERAGEIFS(Cleaned_Data!$K$12:$K$61,Cleaned_Data!$D$12:$D$61,A7,Cleaned_Data!$C$12:$C$61,B7),0) -> 4.3
A8: South | B8: Returning | C8: =_xlfn.COUNTIFS(Cleaned_Data!$D$12:$D$61,A8,Cleaned_Data!$C$12:$C$61,B8) -> 8 | D8: =_xlfn.IFERROR(_xlfn.AVERAGEIFS(Cleaned_Data!$G$12:$G$61,Cleaned_Data!$D$12:$D$61,A8,Cleaned_Data!$C$12:$C$61,B8),0) -> 1312.5 | E8: =_xlfn.IFERROR(_xlfn.AVERAGEIFS(Cleaned_Data!$J$12:$J$61,Cleaned_Data!$D$12:$D$61,A8,Cleaned_Data!$C$12:$C$61,B8),0) -> 41.625 | F8: =_xlfn.IFERROR(_xlfn.AVERAGEIFS(Cleaned_Data!$K$12:$K$61,Cleaned_Data!$D$12:$D$61,A8,Cleaned_Data!$C$12:$C$61,B8),0) -> 3.95
A9: East | B9: New | C9: =_xlfn.COUNTIFS(Cleaned_Data!$D$12:$D$61,A9,Cleaned_Data!$C$12:$C$61,B9) -> 7 | D9: =_xlfn.IFERROR(_xlfn.AVERAGEIFS(Cleaned_Data!$G$12:$G$61,Cleaned_Data!$D$12:$D$61,A9,Cleaned_Data!$C$12:$C$61,B9),0) -> 790 | E9: =_xlfn.IFERROR(_xlfn.AVERAGEIFS(Cleaned_Data!$J$12:$J$61,Cleaned_Data!$D$12:$D$61,A9,Cleaned_Data!$C$12:$C$61,B9),0) -> 29.428571 | F9: =_xlfn.IFERROR(_xlfn.AVERAGEIFS(Cleaned_Data!$K$12:$K$61,Cleaned_Data!$D$12:$D$61,A9,Cleaned_Data!$C$12:$C$61,B9),0) -> 4.1285714
A10: East | B10: Returning | C10: =_xlfn.COUNTIFS(Cleaned_Data!$D$12:$D$61,A10,Cleaned_Data!$C$12:$C$61,B10) -> 1 | D10: =_xlfn.IFERROR(_xlfn.AVERAGEIFS(Cleaned_Data!$G$12:$G$61,Cleaned_Data!$D$12:$D$61,A10,Cleaned_Data!$C$12:$C$61,B10),0) -> 360 | E10: =_xlfn.IFERROR(_xlfn.AVERAGEIFS(Cleaned_Data!$J$12:$J$61,Cleaned_Data!$D$12:$D$61,A10,Cleaned_Data!$C$12:$C$61,B10),0) -> 59 | F10: =_xlfn.IFERROR(_xlfn.AVERAGEIFS(Cleaned_Data!$K$12:$K$61,Cleaned_Data!$D$12:$D$61,A10,Cleaned_Data!$C$12:$C$61,B10),0) -> 3.6
A11: Central | B11: New | C11: =_xlfn.COUNTIFS(Cleaned_Data!$D$12:$D$61,A11,Cleaned_Data!$C$12:$C$61,B11) -> 9 | D11: =_xlfn.IFERROR(_xlfn.AVERAGEIFS(Cleaned_Data!$G$12:$G$61,Cleaned_Data!$D$12:$D$61,A11,Cleaned_Data!$C$12:$C$61,B11),0) -> 451.11111 | E11: =_xlfn.IFERROR(_xlfn.AVERAGEIFS(Cleaned_Data!$J$12:$J$61,Cleaned_Data!$D$12:$D$61,A11,Cleaned_Data!$C$12:$C$61,B11),0) -> 32.777778 | F11: =_xlfn.IFERROR(_xlfn.AVERAGEIFS(Cleaned_Data!$K$12:$K$61,Cleaned_Data!$D$12:$D$61,A11,Cleaned_Data!$C$12:$C$61,B11),0) -> 4.2222222
A12: Central | B12: Returning | C12: =_xlfn.COUNTIFS(Cleaned_Data!$D$12:$D$61,A12,Cleaned_Data!$C$12:$C$61,B12) -> 4 | D12: =_xlfn.IFERROR(_xlfn.AVERAGEIFS(Cleaned_Data!$G$12:$G$61,Cleaned_Data!$D$12:$D$61,A12,Cleaned_Data!$C$12:$C$61,B12),0) -> 870 | E12: =_xlfn.IFERROR(_xlfn.AVERAGEIFS(Cleaned_Data!$J$12:$J$61,Cleaned_Data!$D$12:$D$61,A12,Cleaned_Data!$C$12:$C$61,B12),0) -> 28.5 | F12: =_xlfn.IFERROR(_xlfn.AVERAGEIFS(Cleaned_Data!$K$12:$K$61,Cleaned_Data!$D$12:$D$61,A12,Cleaned_Data!$C$12:$C$61,B12),0) -> 4.3
A13: GRAND TOTAL | C13: =SUM(C5:C12) -> 50 | D13: =AVERAGE(Cleaned_Data!$G$12:$G$61) -> 733.4 | E13: =AVERAGE(Cleaned_Data!$J$12:$J$61) -> 36.02 | F13: =AVERAGE(Cleaned_Data!$K$12:$K$61) -> 4.08

Sheet Charts
A1: CHARTS (Task 15)
A3: Chart 1 Data: Orders by Delivery Area
A4: Area | B4: Number of Orders
A5: North | B5: =COUNTIF(Cleaned_Data!$D$12:$D$61,A5) -> 13
A6: South | B6: =COUNTIF(Cleaned_Data!$D$12:$D$61,A6) -> 16
A7: East | B7: =COUNTIF(Cleaned_Data!$D$12:$D$61,A7) -> 8
A8: Central | B8: =COUNTIF(Cleaned_Data!$D$12:$D$61,A8) -> 13
A11: Chart 2 Data: Average Order Value by Customer Type
A12: Customer_Type | B12: Average Order Value
A13: New | B13: =_xlfn.AVERAGEIF(Cleaned_Data!$C$12:$C$61,A13,Cleaned_Data!$G$12:$G$61) -> 576.12903
A14: Returning | B14: =_xlfn.AVERAGEIF(Cleaned_Data!$C$12:$C$61,A14,Cleaned_Data!$G$12:$G$61) -> 990
A17: Chart 3 Data: Average Rating by Delivery Area
A18: Area | B18: Average Rating
A19: North | B19: =_xlfn.AVERAGEIF(Cleaned_Data!$D$12:$D$61,A19,Cleaned_Data!$K$12:$K$61) -> 3.8692308
A20: South | B20: =_xlfn.AVERAGEIF(Cleaned_Data!$D$12:$D$61,A20,Cleaned_Data!$K$12:$K$61) -> 4.125
A21: East | B21: =_xlfn.AVERAGEIF(Cleaned_Data!$D$12:$D$61,A21,Cleaned_Data!$K$12:$K$61) -> 4.0625
A22: Central | B22: =_xlfn.AVERAGEIF(Cleaned_Data!$D$12:$D$61,A22,Cleaned_Data!$K$12:$K$61) -> 4.2461538

Sheet Top_5_Orders
A1: TOP 5 ORDERS BY ORDER VALUE (Task 17)
A2: Ranked using a tie-safe rank helper (RANK.EQ + COUNTIF for tie-breaking) so orders with equal Order_Value each get a distinct rank, then INDEX/MATCH pulls the matching row from Cleaned_Data.
H3: Helper: TieRank | I3: Helper: Order_ID
A4: Rank | B4: Order_ID | C4: Order_Value | D4: Customer_Type | E4: Area | F4: Order_Type | H4: =RANK(Cleaned_Data!G12,Cleaned_Data!$G$12:$G$61) -> 45 | I4: =Cleaned_Data!A12 -> FD10000
A5: 1 | B5: =INDEX($I$4:$I$53,MATCH(1,$H$4:$H$53,0)) -> FD10012 | C5: =INDEX(Cleaned_Data!$G$12:$G$61,MATCH(B5,Cleaned_Data!$A$12:$A$61,0)) -> 2500 | D5: =INDEX(Cleaned_Data!$C$12:$C$61,MATCH(B5,Cleaned_Data!$A$12:$A$61,0)) -> Returning | E5: =INDEX(Cleaned_Data!$D$12:$D$61,MATCH(B5,Cleaned_Data!$A$12:$A$61,0)) -> South | F5: =INDEX(Cleaned_Data!$E$12:$E$61,MATCH(B5,Cleaned_Data!$A$12:$A$61,0)) -> Large | H5: =RANK(Cleaned_Data!G13,Cleaned_Data!$G$12:$G$61)+COUNTIF(Cleaned_Data!$G$12:G12,Cleaned_Data!G13) -> 33 | I5: =Cleaned_Data!A13 -> FD10001
A6: 2 | B6: =INDEX($I$4:$I$53,MATCH(2,$H$4:$H$53,0)) -> FD10042 | C6: =INDEX(Cleaned_Data!$G$12:$G$61,MATCH(B6,Cleaned_Data!$A$12:$A$61,0)) -> 2500 | D6: =INDEX(Cleaned_Data!$C$12:$C$61,MATCH(B6,Cleaned_Data!$A$12:$A$61,0)) -> Returning | E6: =INDEX(Cleaned_Data!$D$12:$D$61,MATCH(B6,Cleaned_Data!$A$12:$A$61,0)) -> Central | F6: =INDEX(Cleaned_Data!$E$12:$E$61,MATCH(B6,Cleaned_Data!$A$12:$A$61,0)) -> Combo | H6: =RANK(Cleaned_Data!G14,Cleaned_Data!$G$12:$G$61)+COUNTIF(Cleaned_Data!$G$12:G13,Cleaned_Data!G14) -> 48 | I6: =Cleaned_Data!A14 -> FD10002
A7: 3 | B7: =INDEX($I$4:$I$53,MATCH(3,$H$4:$H$53,0)) -> FD10043 | C7: =INDEX(Cleaned_Data!$G$12:$G$61,MATCH(B7,Cleaned_Data!$A$12:$A$61,0)) -> 2000 | D7: =INDEX(Cleaned_Data!$C$12:$C$61,MATCH(B7,Cleaned_Data!$A$12:$A$61,0)) -> Returning | E7: =INDEX(Cleaned_Data!$D$12:$D$61,MATCH(B7,Cleaned_Data!$A$12:$A$61,0)) -> North | F7: =INDEX(Cleaned_Data!$E$12:$E$61,MATCH(B7,Cleaned_Data!$A$12:$A$61,0)) -> Large | H7: =RANK(Cleaned_Data!G15,Cleaned_Data!$G$12:$G$61)+COUNTIF(Cleaned_Data!$G$12:G14,Cleaned_Data!G15) -> 49 | I7: =Cleaned_Data!A15 -> FD10003
A8: 4 | B8: =INDEX($I$4:$I$53,MATCH(4,$H$4:$H$53,0)) -> FD10013 | C8: =INDEX(Cleaned_Data!$G$12:$G$61,MATCH(B8,Cleaned_Data!$A$12:$A$61,0)) -> 1750 | D8: =INDEX(Cleaned_Data!$C$12:$C$61,MATCH(B8,Cleaned_Data!$A$12:$A$61,0)) -> Returning | E8: =INDEX(Cleaned_Data!$D$12:$D$61,MATCH(B8,Cleaned_Data!$A$12:$A$61,0)) -> South | F8: =INDEX(Cleaned_Data!$E$12:$E$61,MATCH(B8,Cleaned_Data!$A$12:$A$61,0)) -> Combo | H8: =RANK(Cleaned_Data!G16,Cleaned_Data!$G$12:$G$61)+COUNTIF(Cleaned_Data!$G$12:G15,Cleaned_Data!G16) -> 34 | I8: =Cleaned_Data!A16 -> FD10004
A9: 5 | B9: =INDEX($I$4:$I$53,MATCH(5,$H$4:$H$53,0)) -> FD10028 | C9: =INDEX(Cleaned_Data!$G$12:$G$61,MATCH(B9,Cleaned_Data!$A$12:$A$61,0)) -> 1750 | D9: =INDEX(Cleaned_Data!$C$12:$C$61,MATCH(B9,Cleaned_Data!$A$12:$A$61,0)) -> New | E9: =INDEX(Cleaned_Data!$D$12:$D$61,MATCH(B9,Cleaned_Data!$A$12:$A$61,0)) -> East | F9: =INDEX(Cleaned_Data!$E$12:$E$61,MATCH(B9,Cleaned_Data!$A$12:$A$61,0)) -> Regular | H9: =RANK(Cleaned_Data!G17,Cleaned_Data!$G$12:$G$61)+COUNTIF(Cleaned_Data!$G$12:G16,Cleaned_Data!G17) -> 27 | I9: =Cleaned_Data!A17 -> FD10005
H10: =RANK(Cleaned_Data!G18,Cleaned_Data!$G$12:$G$61)+COUNTIF(Cleaned_Data!$G$12:G17,Cleaned_Data!G18) -> 28 | I10: =Cleaned_Data!A18 -> FD10006
H11: =RANK(Cleaned_Data!G19,Cleaned_Data!$G$12:$G$61)+COUNTIF(Cleaned_Data!$G$12:G18,Cleaned_Data!G19) -> 32 | I11: =Cleaned_Data!A19 -> FD10007
H12: =RANK(Cleaned_Data!G20,Cleaned_Data!$G$12:$G$61)+COUNTIF(Cleaned_Data!$G$12:G19,Cleaned_Data!G20) -> 10 | I12: =Cleaned_Data!A20 -> FD10008
H13: =RANK(Cleaned_Data!G21,Cleaned_Data!$G$12:$G$61)+COUNTIF(Cleaned_Data!$G$12:G20,Cleaned_Data!G21) -> 21 | I13: =Cleaned_Data!A21 -> FD10009
H14: =RANK(Cleaned_Data!G22,Cleaned_Data!$G$12:$G$61)+COUNTIF(Cleaned_Data!$G$12:G21,Cleaned_Data!G22) -> 20 | I14: =Cleaned_Data!A22 -> FD10010
H15: =RANK(Cleaned_Data!G23,Cleaned_Data!$G$12:$G$61)+COUNTIF(Cleaned_Data!$G$12:G22,Cleaned_Data!G23) -> 7 | I15: =Cleaned_Data!A23 -> FD10011
H16: =RANK(Cleaned_Data!G24,Cleaned_Data!$G$12:$G$61)+COUNTIF(Cleaned_Data!$G$12:G23,Cleaned_Data!G24) -> 1 | I16: =Cleaned_Data!A24 -> FD10012
H17: =RANK(Cleaned_Data!G25,Cleaned_Data!$G$12:$G$61)+COUNTIF(Cleaned_Data!$G$12:G24,Cleaned_Data!G25) -> 4 | I17: =Cleaned_Data!A25 -> FD10013
H18: =RANK(Cleaned_Data!G26,Cleaned_Data!$G$12:$G$61)+COUNTIF(Cleaned_Data!$G$12:G25,Cleaned_Data!G26) -> 11 | I18: =Cleaned_Data!A26 -> FD10014
H19: =RANK(Cleaned_Data!G27,Cleaned_Data!$G$12:$G$61)+COUNTIF(Cleaned_Data!$G$12:G26,Cleaned_Data!G27) -> 42 | I19: =Cleaned_Data!A27 -> FD10015
H20: =RANK(Cleaned_Data!G28,Cleaned_Data!$G$12:$G$61)+COUNTIF(Cleaned_Data!$G$12:G27,Cleaned_Data!G28) -> 23 | I20: =Cleaned_Data!A28 -> FD10016
H21: =RANK(Cleaned_Data!G29,Cleaned_Data!$G$12:$G$61)+COUNTIF(Cleaned_Data!$G$12:G28,Cleaned_Data!G29) -> 14 | I21: =Cleaned_Data!A29 -> FD10017
... H53: =RANK(Cleaned_Data!G61,Cleaned_Data!$G$12:$G$61)+COUNTIF(Cleaned_Data!$G$12:G60,Cleaned_Data!G61) -> 47 | I53: =Cleaned_Data!A61 -> FD10049

Sheet Recommendations
A1: PATTERNS & EVIDENCE-BASED RECOMMENDATIONS (Tasks 18-19)
A3: Task 18: Important Patterns Identified
A4: • Delivery time drives ratings down
A5: Delivery_Minutes and Rating have a correlation of about -0.70 (see Descriptive_Stats, Task 11-12): the longer a delivery takes, the lower the customer rates the order. This is the strongest relationship in the dataset.
A7: • North is the slowest and lowest-rated area
A8: North has the highest average combined prep+delivery time (~57 min) of all four areas and the lowest average rating (~3.87), while Central is fastest overall and has the highest average rating (~4.25) — consistent with the delivery-time/rating pattern above.
A10: • Returning customers order more per transaction, not more often
A11: Returning customers place fewer total orders than New customers but spend nearly double per order on average (see Descriptive_Stats, Task 4) — order value, not order frequency, is where returning customers add value.
A13: • Promo usage is linked to lower average order value and rating, not higher
A14: Orders using a promo have a lower average order value and a slightly lower average rating than orders placed without a promo (see Descriptive_Stats, Task 13-14). This suggests current promos may be attracting smaller, price-sensitive orders rather than driving larger baskets.
A16: • Regular orders rate best; Combo orders rate worst
A17: Regular order types have the highest average rating despite the lowest average order value, while Combo orders have the lowest average rating despite a mid-range order value — larger/combined orders may be harder to prepare and deliver without quality slipping.
... A30: Returning customers already spend ~72% more per order than New customers. Loyalty programs should focus on increasing basket size for New customers (e.g., first-order incentives tied to order value) rather than purely on repeat-visit frequency, since that is where Returning customers already excel.

Sheet Sheet1
